2023-02-05 04:01:34,883 - telegram.ext._application - INFO - Application started
2023-02-05 04:01:58,673 - root - INFO - Start program.
2023-02-05 04:02:03,249 - root - INFO - Start main menu.
2023-02-05 04:02:12,184 - root - INFO - Start menu with complex.
2023-02-05 04:02:25,227 - telegram.ext._application - ERROR - No error handlers are registered, logging exception.
Traceback (most recent call last):
  File "C:\Users\ADMIN\AppData\Roaming\Python\Python311\site-packages\telegram\ext\_application.py", line 1063, in process_update
    await coroutine
  File "C:\Users\ADMIN\AppData\Roaming\Python\Python311\site-packages\telegram\ext\_handler.py", line 141, in handle_update
    return await self.callback(update, context)
                 ^^^^^^^^^^^^^^^^^^^^^^^^^^^^^^
TypeError: Quitter.__call__() takes from 1 to 2 positional arguments but 3 were given
2023-02-05 04:02:34,224 - root - INFO - Start main menu.
2023-02-05 04:02:38,224 - telegram.ext._application - ERROR - No error handlers are registered, logging exception.
Traceback (most recent call last):
  File "C:\Users\ADMIN\AppData\Roaming\Python\Python311\site-packages\telegram\ext\_application.py", line 1063, in process_update
    await coroutine
  File "C:\Users\ADMIN\AppData\Roaming\Python\Python311\site-packages\telegram\ext\_handler.py", line 141, in handle_update
    return await self.callback(update, context)
                 ^^^^^^^^^^^^^^^^^^^^^^^^^^^^^^
TypeError: Quitter.__call__() takes from 1 to 2 positional arguments but 3 were given
2023-02-05 04:05:29,218 - telegram.ext._updater - ERROR - Error while getting Updates: Conflict: terminated by other getUpdates request; make sure that only one bot instance is running
2023-02-05 04:05:29,218 - telegram.ext._application - ERROR - No error handlers are registered, logging exception.
Traceback (most recent call last):
  File "C:\Users\ADMIN\AppData\Roaming\Python\Python311\site-packages\telegram\ext\_updater.py", line 600, in _network_loop_retry
    if not await action_cb():
           ^^^^^^^^^^^^^^^^^
  File "C:\Users\ADMIN\AppData\Roaming\Python\Python311\site-packages\telegram\ext\_updater.py", line 327, in polling_action_cb
    raise exc
  File "C:\Users\ADMIN\AppData\Roaming\Python\Python311\site-packages\telegram\ext\_updater.py", line 312, in polling_action_cb
    updates = await self.bot.get_updates(
              ^^^^^^^^^^^^^^^^^^^^^^^^^^^
  File "C:\Users\ADMIN\AppData\Roaming\Python\Python311\site-packages\telegram\ext\_extbot.py", line 524, in get_updates
    updates = await super().get_updates(
              ^^^^^^^^^^^^^^^^^^^^^^^^^^
  File "C:\Users\ADMIN\AppData\Roaming\Python\Python311\site-packages\telegram\_bot.py", line 334, in decorator
    result = await func(*args, **kwargs)  # skipcq: PYL-E1102
             ^^^^^^^^^^^^^^^^^^^^^^^^^^^
  File "C:\Users\ADMIN\AppData\Roaming\Python\Python311\site-packages\telegram\_bot.py", line 3584, in get_updates
    await self._post(
  File "C:\Users\ADMIN\AppData\Roaming\Python\Python311\site-packages\telegram\_bot.py", line 422, in _post
    return await self._do_post(
           ^^^^^^^^^^^^^^^^^^^^
  File "C:\Users\ADMIN\AppData\Roaming\Python\Python311\site-packages\telegram\ext\_extbot.py", line 306, in _do_post
    return await super()._do_post(
           ^^^^^^^^^^^^^^^^^^^^^^^
  File "C:\Users\ADMIN\AppData\Roaming\Python\Python311\site-packages\telegram\_bot.py", line 453, in _do_post
    return await request.post(
           ^^^^^^^^^^^^^^^^^^^
  File "C:\Users\ADMIN\AppData\Roaming\Python\Python311\site-packages\telegram\request\_baserequest.py", line 165, in post
    result = await self._request_wrapper(
             ^^^^^^^^^^^^^^^^^^^^^^^^^^^^
  File "C:\Users\ADMIN\AppData\Roaming\Python\Python311\site-packages\telegram\request\_baserequest.py", line 330, in _request_wrapper
    raise Conflict(message)
telegram.error.Conflict: Conflict: terminated by other getUpdates request; make sure that only one bot instance is running
2023-02-05 04:05:34,290 - telegram.ext._updater - ERROR - Error while getting Updates: Conflict: terminated by other getUpdates request; make sure that only one bot instance is running
2023-02-05 04:05:34,290 - telegram.ext._application - ERROR - No error handlers are registered, logging exception.
Traceback (most recent call last):
  File "C:\Users\ADMIN\AppData\Roaming\Python\Python311\site-packages\telegram\ext\_updater.py", line 600, in _network_loop_retry
    if not await action_cb():
           ^^^^^^^^^^^^^^^^^
  File "C:\Users\ADMIN\AppData\Roaming\Python\Python311\site-packages\telegram\ext\_updater.py", line 327, in polling_action_cb
    raise exc
  File "C:\Users\ADMIN\AppData\Roaming\Python\Python311\site-packages\telegram\ext\_updater.py", line 312, in polling_action_cb
    updates = await self.bot.get_updates(
              ^^^^^^^^^^^^^^^^^^^^^^^^^^^
  File "C:\Users\ADMIN\AppData\Roaming\Python\Python311\site-packages\telegram\ext\_extbot.py", line 524, in get_updates
    updates = await super().get_updates(
              ^^^^^^^^^^^^^^^^^^^^^^^^^^
  File "C:\Users\ADMIN\AppData\Roaming\Python\Python311\site-packages\telegram\_bot.py", line 334, in decorator
    result = await func(*args, **kwargs)  # skipcq: PYL-E1102
             ^^^^^^^^^^^^^^^^^^^^^^^^^^^
  File "C:\Users\ADMIN\AppData\Roaming\Python\Python311\site-packages\telegram\_bot.py", line 3584, in get_updates
    await self._post(
  File "C:\Users\ADMIN\AppData\Roaming\Python\Python311\site-packages\telegram\_bot.py", line 422, in _post
    return await self._do_post(
           ^^^^^^^^^^^^^^^^^^^^
  File "C:\Users\ADMIN\AppData\Roaming\Python\Python311\site-packages\telegram\ext\_extbot.py", line 306, in _do_post
    return await super()._do_post(
           ^^^^^^^^^^^^^^^^^^^^^^^
  File "C:\Users\ADMIN\AppData\Roaming\Python\Python311\site-packages\telegram\_bot.py", line 453, in _do_post
    return await request.post(
           ^^^^^^^^^^^^^^^^^^^
  File "C:\Users\ADMIN\AppData\Roaming\Python\Python311\site-packages\telegram\request\_baserequest.py", line 165, in post
    result = await self._request_wrapper(
             ^^^^^^^^^^^^^^^^^^^^^^^^^^^^
  File "C:\Users\ADMIN\AppData\Roaming\Python\Python311\site-packages\telegram\request\_baserequest.py", line 330, in _request_wrapper
    raise Conflict(message)
telegram.error.Conflict: Conflict: terminated by other getUpdates request; make sure that only one bot instance is running
2023-02-05 04:40:50,307 - telegram.ext._application - INFO - Application started
2023-02-05 04:41:03,379 - root - INFO - Start program.
2023-02-05 04:41:07,056 - root - INFO - Start main menu.
2023-02-05 04:41:11,310 - root - INFO - Start menu with rational.
2023-02-05 04:41:28,029 - root - INFO - Start menu division.
2023-02-05 04:41:34,444 - root - INFO - Start menu with rational.
2023-02-05 04:41:38,602 - root - INFO - Start main menu.
2023-02-05 04:41:42,831 - root - INFO - Stop program. See you soon, {update.effective_user.first_name}!
2023-02-05 04:50:20,983 - telegram.ext._application - INFO - Application started
2023-02-05 04:50:29,331 - root - INFO - Start program.
2023-02-05 04:50:32,115 - root - INFO - Start main menu.
2023-02-05 04:50:35,516 - root - INFO - Start menu with rational.
2023-02-05 04:50:38,790 - root - INFO - Start main menu.
2023-02-05 04:50:42,728 - root - INFO - Stop program
